Workbook

Sheet Data BBK
A1: NoBukti | B1: TglKeluar | C1: Keterangan | E1: Peminta | F1: KdBrg | G1: namabrg | H1: satprimer | I1: Nopol | K1: KM | L1: Jenis | M1: PT | N1: Pemakaian | O1: QtyS | P1: Harga | Q1: SubTotal | R1: User
A2: 1-BBK22010832 | B2: 44591 | C2: TAGIHAN PERSADA | E2: MEKANIK | F2: ACCU.002 | G2: ACCU NS70 INCHOE | H2: PCS | I2: S 9159 UJ | K2: 2 | L2: TRONTON | M2: DAMAI ELOK ANDALAN | N2: TAGIHAN PERSADA | O2: 2 | P2: 1118040 | Q2: 2236080 | R2: ISMAIL
A3: 1-BBK22010033 | B3: 44565 | C3: ACCU | E3: NANANG | F3: ACCU.008 | G3: ACCU N100 INCHOE | H3: PCS | I3: L 9278 UJ | K3: 123 | L3: COLT DIESEL | M3: DAMAI ELOK ANDALAN | N3: ARISTIANUS | O3: 1 | P3: 1280000 | Q3: 1280000 | R3: ISMAIL
A4: 1-BBK22010105 | B4: 44567 | C4: STORING SBY | E4: AGIL | F4: ACCU.008 | G4: ACCU N100 INCHOE | H4: PCS | I4: S 9352 UJ | K4: 1 | L4: COLT DIESEL | M4: PETRA ESA TRANSINDO | O4: 1 | P4: 1280000 | Q4: 1280000 | R4: ISMAIL
A5: 1-BBK22010277 | B5: 44573 | C5: ACCU | E5: AGIL | F5: ACCU.008 | G5: ACCU N100 INCHOE | H5: PCS | I5: S 8985 UJ | K5: 145245 | L5: COLT DIESEL | M5: CAHAYA UNGGUL SENTOSA | O5: 1 | P5: 1280000 | Q5: 1280000 | R5: ISMAIL
A6: 1-BBK22010278 | B6: 44573 | C6: ACCU | E6: IKWAN | F6: ACCU.008 | G6: ACCU N100 INCHOE | H6: PCS | I6: S 9012 UJ | K6: 211423 | L6: COLT DIESEL | M6: FAJAR ABADI KARYATAMA | O6: 1 | P6: 1280000 | Q6: 1280000 | R6: ISMAIL
A7: 1-BBK22010335 | B7: 44575 | C7: AIR ACCU | E7: IKWAN | F7: ACCU.009 | G7: AIR ACCU | H7: LTR | I7: S 9439 UJ | K7: 208757 | L7: COLT DIESEL | M7: ABADI SARANA INTITRANS | N7: KOSIM | O7: 1 | P7: 5413.75 | Q7: 5413.75 | R7: ISMAIL
A8: 1-BBK22010339 | B8: 44575 | C8: PER | E8: ARIF | F8: ACCU.009 | G8: AIR ACCU | H8: LTR | I8: S 9172 UJ | K8: 326495 | L8: TRONTON | M8: CAHAYA UNGGUL SENTOSA | N8: SUN'AN | O8: 1 | P8: 5413.75 | Q8: 5413.75 | R8: ISMAIL
A9: 1-BBK22010250 | B9: 44573 | C9: GCU | E9: BUDI | F9: ACCU.009 | G9: AIR ACCU | H9: LTR | I9: S 9259 UK | K9: 71007 | L9: COLT DIESEL | M9: INTI SUMBER PELANGI | N9: KUSNO | O9: 1 | P9: 5413.75 | Q9: 5413.75 | R9: ISMAIL
A10: 1-BBK22010347 | B10: 44575 | C10: AIR ACCU | E10: NANANG | F10: ACCU.009 | G10: AIR ACCU | H10: LTR | I10: S 9228 UJ | K10: 310164 | L10: TRONTON | M10: CAHAYA UNGGUL SENTOSA | O10: 1 | P10: 5413.75 | Q10: 5413.75 | R10: ISMAIL
A11: 1-BBK22010063 | B11: 44566 | C11: TAGIHAN PERSADA | E11: MEKANIK | F11: ACCU.009 | G11: AIR ACCU | H11: LTR | I11: S 8790 UJ | K11: 2 | L11: DUMP TRUCK BESAR | M11: OMEGA MEGA GEMILANG | N11: TAGIHAN PERSADA | O11: 2 | P11: 5413.75 | Q11: 10827.5 | R11: ISMAIL
A12: 1-BBK22010204 | B12: 44571 | C12: GCU | E12: BAYU | F12: ACCU.009 | G12: AIR ACCU | H12: LTR | I12: S 8962 UJ | K12: 241290 | L12: COLT DIESEL | M12: JASA ELOK TRANSINDO | N12: ANWAR | O12: 2 | P12: 5413.75 | Q12: 10827.5 | R12: ISMAIL
A13: 1-BBK22010845 | B13: 44592 | C13: SHOCKBREAKER | E13: BUDI | F13: ACCU.009 | G13: AIR ACCU | H13: LTR | I13: S 9224 UJ | K13: 318355 | L13: TRONTON | M13: KARYA PRIMA REJEKI | N13: SUGITA | O13: 2 | P13: 5209.3023 | Q13: 10418.605 | R13: ISMAIL
A14: 1-BBK22020013 | B14: 44594 | C14: OLI | E14: NIAM | F14: ACCU.009 | G14: AIR ACCU | H14: LTR | I14: L 8951 UJ | K14: 115621 | L14: COLT DIESEL | M14: BANGKIT NUSA INDOTRANS | N14: ARI | O14: 2 | P14: 5209.3023 | Q14: 10418.605 | R14: ISMAIL
A15: 1-BBK22020163 | B15: 44597 | C15: AIR ACCUI | E15: AGUS | F15: ACCU.009 | G15: AIR ACCU | H15: LTR | I15: L 8962 UJ | K15: 129915 | L15: COLT DIESEL | M15: ABADI SARANA INTITRANS | O15: 2 | P15: 5209.3023 | Q15: 10418.605 | R15: ISMAIL
A16: 1-BBK22020177 | B16: 44599 | C16: BOHLAM | E16: WAHYU | F16: ACCU.009 | G16: AIR ACCU | H16: LTR | I16: S 9394 UJ | K16: 193362 | L16: COLT DIESEL | M16: HARMONI CAHAYA LESTARI | N16: SYUKUR | O16: 2 | P16: 5209.3023 | Q16: 10418.605 | R16: ISMAIL
A17: 1-BBK22010669 | B17: 44586 | C17: KELISTRIKAN | E17: KARIS | F17: ACCU.009 | G17: AIR ACCU | H17: LTR | I17: S 9577 UJ | K17: 163194 | L17: COLT DIESEL | M17: ESA SUMBER ANUGERAH | O17: 1 | P17: 8000 | Q17: 8000 | R17: ISMAIL
A18: 1-BBK22010001 | B18: 44564 | C18: ACCU N100 | E18: BAYU | F18: ACCU.018 | G18: ACCU FASTER N100 | H18: PCS | I18: S 9472 UJ | K18: 176815 | L18: COLT DIESEL | M18: FORTUNA PERSADA INTI | N18: MAULANA | O18: 1 | P18: 1184553.2 | Q18: 1184553.2 | R18: ISMAIL
A19: 1-BBK22010003 | B19: 44564 | C19: ACCU TEKOR | E19: BAYU | F19: ACCU.018 | G19: ACCU FASTER N100 | H19: PCS | I19: S 9122 UJ | K19: 1 | L19: COLT DIESEL | M19: ESA SUMBER ANUGERAH | O19: 1 | P19: 1184553.2 | Q19: 1184553.2 | R19: ISMAIL
A20: 1-BBK22010384 | B20: 44578 | C20: ACCU HILANG | E20: NANANG | F20: ACCU.018 | G20: ACCU FASTER N100 | H20: PCS | I20: S 9492 UJ | K20: 1 | L20: COLT DIESEL | M20: LESTARI ERA MAKMUR | N20: AGUS SUYONO | O20: 1 | P20: 1185600 | Q20: 1185600 | R20: ISMAIL
A21: 1-BBK22010291 | B21: 44573 | C21: ACCU | E21: NANANG | F21: ACCU.019 | G21: ACCU NS70 FASTER | H21: PCS | I21: B 9363 PYU | K21: 12345 | L21: DUMP TRUCK BESAR | M21: HAKIKI TRANSINDO SEJATI | O21: 1 | P21: 774488 | Q21: 774488 | R21: ISMAIL
A22: 1-BBK22010654 | B22: 44585 | C22: ACCU | E22: SUPRI | F22: ACCU.020 | G22: ACCU N50Z FASTER | H22: PCS | I22: S 9399 UR | K22: 0 | L22: COLT DIESEL | M22: GALAXY NUSA INDAH | N22: FERDI | O22: 2 | P22: 710363 | Q22: 1420726 | R22: ISMAIL
A23: 1-BBK22010420 | B23: 44579 | C23: BATRE | E23: IBNU | F23: ATK.012 | G23: BATRAY ABC | H23: PCS | I23: LAIN2 | K23: 0 | L23: LAIN2 | M23: LAIN2 | O23: 5 | P23: 7000 | Q23: 35000 | R23: ISMAIL
A24: 1-BBK22010136 | B24: 44568 | C24: TRAFFIC BOTTON | E24: SECURITY | F24: ATK.012 | G24: BATRAY ABC | H24: PCS | I24: LAIN2 | K24: 0 | L24: LAIN2 | M24: LAIN2 | N24: SECURITY | O24: 4 | P24: 5000 | Q24: 20000 | R24: ISMAIL
A25: 1-BBK22010320 | B25: 44575 | C25: KERTAS BUFALO DAN RAK KERTAS | E25: KANTOR | F25: ATK.025 | G25: KERTAS BUFALO | H25: REM | I25: LAIN2 | K25: 0 | L25: LAIN2 | M25: LAIN2 | N25: KANTOR | O25: 1 | P25: 25000 | Q25: 25000 | R25: ISMAIL
A26: 1-BBK22010072 | B26: 44566 | C26: MOUSE | E26: RIMA | F26: ATK.037 | G26: MOUSE | H26: PCS | I26: LAIN2 | K26: 0 | L26: LAIN2 | M26: LAIN2 | N26: RIMA | O26: 1 | P26: 130000 | Q26: 130000 | R26: ISMAIL
A27: 1-BBK22010552 | B27: 44581 | C27: MOUSE | E27: KANTOR | F27: ATK.037 | G27: MOUSE | H27: PCS | I27: LAIN2 | K27: 0 | L27: LAIN2 | M27: LAIN2 | N27: KANTOR | O27: 2 | P27: 90000 | Q27: 180000 | R27: ISMAIL
A28: 1-BBK22010073 | B28: 44566 | C28: STAPLER | E28: HARYO | F28: ATK.043 | G28: STAPLER | H28: PCS | I28: LAIN2 | K28: 0 | L28: LAIN2 | M28: LAIN2 | N28: HARYO | O28: 1 | P28: 175000 | Q28: 175000 | R28: ISMAIL
A29: 1-BBK22010847 | B29: 44592 | C29: ISI TONER | E29: KANTOR | F29: ATK.052 | G29: REFILL TONER 107A | H29: PCS | I29: LAIN2 | K29: 0 | L29: LAIN2 | M29: LAIN2 | N29: KANTOR | O29: 4 | P29: 95000 | Q29: 380000 | R29: ISMAIL
A30: 1-BBK22010359 | B30: 44576 | C30: KEYBOARD | E30: IBNU | F30: ATK.073 | G30: KEYBOARD | H30: PCS | I30: LAIN2 | K30: 0 | L30: LAIN2 | M30: LAIN2 | O30: 1 | P30: 150000 | Q30: 150000 | R30: ISMAIL
A31: 1-BBK22010361 | B31: 44576 | C31: ATK | E31: IBNU | F31: ATK.081 | G31: CLIP BOARD ESELON/ PAPAN DADA | H31: PCS | I31: LAIN2 | K31: 0 | L31: LAIN2 | M31: LAIN2 | O31: 5 | P31: 15000 | Q31: 75000 | R31: ISMAIL
A32: 1-BBK22010361 | B32: 44576 | C32: ATK | E32: IBNU | F32: ATK.087 | G32: BUKU TULIS | H32: PCS | I32: LAIN2 | K32: 0 | L32: LAIN2 | M32: LAIN2 | O32: 1 | P32: 8000 | Q32: 8000 | R32: ISMAIL
A33: 1-BBK22010201 | B33: 44571 | C33: ISI STAPLER BESAR | E33: KANTOR | F33: ATK.093 | G33: ISI STAPLER BESAR | H33: PACK | I33: LAIN2 | K33: 0 | L33: LAIN2 | M33: LAIN2 | N33: KANTOR | O33: 2 | P33: 14000 | Q33: 28000 | R33: ISMAIL
A34: 1-BBK22010202 | B34: 44571 | C34: SPIDOL BAN TOYO MARKER | E34: ISMAIL | F34: ATK.094 | G34: SPIDOL BAN TOYO MARKER | H34: PCS | I34: LAIN2 | K34: 0 | L34: LAIN2 | M34: LAIN2 | N34: GUDANG | O34: 15 | P34: 3633.33 | Q34: 54499.95 | R34: ISMAIL
A35: 1-BBK22010238 | B35: 44572 | C35: PERBAIKAN CCTV | E35: IBNU | F35: ATK.095 | G35: CCTV HIK 5MP | H35: UNIT | I35: LAIN2 | K35: 1 | L35: LAIN2 | M35: LAIN2 | O35: 1 | P35: 435000 | Q35: 435000 | R35: ISMAIL
A36: 1-BBK22010238 | B36: 44572 | C36: PERBAIKAN CCTV | E36: IBNU | F36: ATK.096 | G36: KONEKTOR BNC CCTV | H36: PCS | I36: LAIN2 | K36: 1 | L36: LAIN2 | M36: LAIN2 | O36: 4 | P36: 5000 | Q36: 20000 | R36: ISMAIL
A37: 1-BBK22010238 | B37: 44572 | C37: PERBAIKAN CCTV | E37: IBNU | F37: ATK.097 | G37: KONEKTOR JACK | H37: PCS | I37: LAIN2 | K37: 1 | L37: LAIN2 | M37: LAIN2 | O37: 2 | P37: 4000 | Q37: 8000 | R37: ISMAIL
A38: 1-BBK22010320 | B38: 44575 | C38: KERTAS BUFALO DAN RAK KERTAS | E38: KANTOR | F38: ATK.099 | G38: RAK KERTAS | H38: SET | I38: LAIN2 | K38: 0 | L38: LAIN2 | M38: LAIN2 | N38: KANTOR | O38: 1 | P38: 95000 | Q38: 95000 | R38: ISMAIL
A39: 1-BBK22010419 | B39: 44579 | C39: UPS | E39: IBNU | F39: ATK.100 | G39: UPS APC 700 VA | H39: PCS | I39: LAIN2 | K39: 0 | L39: LAIN2 | M39: LAIN2 | O39: 1 | P39: 925000 | Q39: 925000 | R39: ISMAIL
A40: 1-BBK22010419 | B40: 44579 | C40: UPS | E40: IBNU | F40: ATK.101 | G40: COLOKAN 3 KAKI | H40: PCS | I40: LAIN2 | K40: 0 | L40: LAIN2 | M40: LAIN2 | O40: 1 | P40: 10000 | Q40: 10000 | R40: ISMAIL
...

Sheet Sheet8
A1: Data returned for Hitung dari Nopol, 103695 (First 1000 rows).
A3: Kueri3[KodeBan] | B3: Kueri3[Nopol] | C3: Kueri3[Merk] | D3: Kueri3[Ukuran] | E3: Kueri3[Tipe] | F3: Kueri3[Tanggal] | G3: Kueri3[Status] | H3: Kueri3[Posisi] | I3: Kueri3[KM] | J3: Kueri3[Keterangan] | K3: Kueri3[Void] | L3: Kueri3[Kondisi] | M3: Kueri3[Status Lepas] | N3: Kueri3[Tanggal Lepas] | O3: Kueri3[KM Lepas] | P3: Kueri3[Keterangan Lepas] | Q3: Kueri3[Kondisi Lepas] | R3: Kueri3[Status Akhir] | S3: Kueri3[Umur] | T3: Kueri3[Unik] | U3: Kueri3[Umur1] | V3: Kueri3[Tanggal (Tahun)] | W3: Kueri3[Tanggal (Kuartal)] | X3: Kueri3[Tanggal (Bulan)] | Y3: Kueri3[Tanggal Lepas (Bulan)] | Z3: Kueri3[Tanggal (Indeks Bulan)] | AA3: Kueri3[Tanggal Lepas (Indeks Bulan)]
A4: 103695 | B4: S 9156 UJ | C4: BS | D4: 1100 | E4: ORI | F4: 44278 | G4: PASANG | H4: 3 | I4: 262376 | J4: PASANG BARU | K4: N | M4: LEPAS | N4: 44584 | O4: 327080 | P4: ROTASI KE POSISI 6 | Q4: MASUK GUDANG | R4: LEPAS | S4: 64704 | T4: 103695-S 9156 UJ-3 | U4: 64704 | V4: 2021 | W4: Qtr1 | X4: Mar | Y4: Jan | Z4: 3 | AA4: 1
A5: 103695 | B5: S 9156 UJ | C5: BS | D5: 1100 | E5: ORI | F5: 44278 | G5: PASANG | H5: 6 | I5: 103695 | J5: PASANG BARU | K5: N | M5: LEPAS | N5: 44596 | O5: 329558 | P5: PECAH | Q5: RUSAK | R5: LEPAS | S5: 225863 | T5: 103695-S 9156 UJ-6 | U5: 225863 | V5: 2021 | W5: Qtr1 | X5: Mar | Y5: Feb | Z5: 3 | AA5: 2

Sheet Query1
A1: ID | B1: KodeBan | C1: Merk | D1: Tipe | E1: Ukuran | F1: Tanggal | G1: Status | H1: Posisi | I1: KM | J1: Keterangan | K1: Void | L1: Kondisi | M1: ID Sebelumnya | N1: ID Selanjutnya | O1: Tanggal 2 | P1: Status 2 | Q1: Posisi 2 | R1: KM 2 | S1: Keterangan 2 | T1: Void 2 | U1: Kondisi 2
A2: 7606 | B2: ICO2055007 | C2: ADV | D2: ORI | E2: 1100 | F2: 44343 | G2: PASANG | H2: 7 | I2: 235337 | J2: PASANG BARU | K2: N | N2: 7607 | O2: 44572 | P2: LEPAS | Q2: 7 | R2: 280778 | S2: WO | T2: N | U2: MASUK GUDANG
A3: 7607 | B3: ICO2055007 | C3: ADV | D3: ORI | E3: 1100 | F3: 44572 | G3: LEPAS | H3: 7 | I3: 280778 | J3: WO | K3: N | L3: MASUK GUDANG | M3: 7606 | N3: 7608 | O3: 44572 | P3: PASANG | Q3: 11 | R3: 325400 | S3: PASANG BAN EX S 9235 UJ | T3: N
A4: 7608 | B4: ICO2055007 | C4: ADV | D4: ORI | E4: 1100 | F4: 44572 | G4: PASANG | H4: 11 | I4: 325400 | J4: PASANG BAN EX S 9235 UJ | K4: N | M4: 7607
A5: 7201 | B5: 01001311303 | C5: CST | D5: ORI | E5: 1100 | F5: 44587 | G5: PASANG | H5: 11 | I5: 312995 | J5: PASANG BAN VULKAMISIR EX S 9156 UJ | K5: N | N5: 7757 | O5: 44593 | P5: LEPAS | Q5: 11 | R5: 313963 | S5: SCP | T5: N | U5: RUSAK
A6: 7757 | B6: 01001311303 | C6: CST | D6: ORI | E6: 1100 | F6: 44593 | G6: LEPAS | H6: 11 | I6: 313963 | J6: SCP | K6: N | L6: RUSAK | M6: 7201
A7: 7751 | B7: 01001352953 | C7: CST | D7: ORI | E7: 1100 | F7: 44494 | G7: PASANG | H7: 3 | I7: 298235 | J7: PASANG BAN EX | K7: N | N7: 7752 | O7: 44596 | P7: LEPAS | Q7: 3 | R7: 323234 | S7: ROTASI KE POSISI 11 | T7: N | U7: MASUK GUDANG
A8: 7752 | B8: 01001352953 | C8: CST | D8: ORI | E8: 1100 | F8: 44596 | G8: LEPAS | H8: 3 | I8: 323234 | J8: ROTASI KE POSISI 11 | K8: N | L8: MASUK GUDANG | M8: 7751
A9: 7754 | B9: 01001352953 | C9: CST | D9: ORI | E9: 1100 | F9: 44494 | G9: PASANG | H9: 11 | I9: 298235 | J9: PASANG BAN EX | K9: N
A10: 7610 | B10: 01001352953 | C10: CST | D10: ORI | E10: 1100 | F10: 44545 | G10: PASANG | H10: 2 | I10: 323835 | J10: PASANG BAN EX S 9068 UJ | K10: N | N10: 7613 | O10: 44565 | P10: LEPAS | Q10: 2 | R10: 327560 | S10: WO | T10: N | U10: RUSAK
A11: 7613 | B11: 01001352953 | C11: CST | D11: ORI | E11: 1100 | F11: 44565 | G11: LEPAS | H11: 2 | I11: 327560 | J11: WO | K11: N | L11: RUSAK | M11: 7610
A12: 7171 | B12: 01001352961 | C12: CST | D12: ORI | E12: 1100 | F12: 44584 | G12: LEPAS | H12: 7 | I12: 312462 | J12: SEPARATION | K12: N | L12: RUSAK | M12: 4654 | N12: 7276 | O12: 44584 | P12: PASANG | Q12: 11 | R12: 357472 | S12: PASANG BAN EX S 9196 UJ | T12: N
A13: 7276 | B13: 01001352961 | C13: CST | D13: ORI | E13: 1100 | F13: 44584 | G13: PASANG | H13: 11 | I13: 357472 | J13: PASANG BAN EX S 9196 UJ | K13: N | M13: 7171
A14: 4654 | B14: 01001352961 | C14: CST | D14: ORI | E14: 1100 | F14: 44048 | G14: PASANG | H14: 7 | I14: 192408 | J14: PASANG BARU | K14: N | N14: 7171 | O14: 44584 | P14: LEPAS | Q14: 7 | R14: 312462 | S14: SEPARATION | T14: N | U14: RUSAK
A15: 7351 | B15: 01001366911 | C15: CST | D15: ORI | E15: 1100 | F15: 44306 | G15: PASANG | H15: 7 | I15: 290746 | J15: PASANG BAN EX | K15: N | N15: 7354 | O15: 44569 | P15: LEPAS | Q15: 7 | R15: 290746 | S15: WO | T15: N | U15: MASUK GUDANG
A16: 7354 | B16: 01001366911 | C16: CST | D16: ORI | E16: 1100 | F16: 44569 | G16: LEPAS | H16: 7 | I16: 290746 | J16: WO | K16: N | L16: MASUK GUDANG | M16: 7351 | N16: 7359 | O16: 44570 | P16: PASANG | Q16: 11 | R16: 338849 | S16: PASANG BAN EX S 9194 UJ | T16: N
A17: 7359 | B17: 01001366911 | C17: CST | D17: ORI | E17: 1100 | F17: 44570 | G17: PASANG | H17: 11 | I17: 338849 | J17: PASANG BAN EX S 9194 UJ | K17: N | M17: 7354
A18: 4267 | B18: 01001495573 | C18: CST | D18: ORI | E18: 750 | F18: 44359 | G18: PASANG | H18: 7 | I18: 211724 | J18: PASANG BAN EX | K18: N | N18: 7941 | O18: 44601 | P18: LEPAS | Q18: 7 | R18: 256795 | S18: WO | T18: N | U18: RUSAK
A19: 7941 | B19: 01001495573 | C19: CST | D19: ORI | E19: 750 | F19: 44601 | G19: LEPAS | H19: 7 | I19: 256795 | J19: WO | K19: N | L19: RUSAK | M19: 4267
A20: 764 | B20: 01001518713 | C20: CST | D20: ORI | E20: 750 | F20: 44120 | G20: PASANG | H20: 7 | I20: 106211 | J20: PASANG BARU | K20: N
A21: 307 | B21: 01001532125 | C21: CST | D21: ORI | E21: 750 | F21: 44120 | G21: PASANG | H21: 6 | I21: 93229 | J21: PASANG BARU | K21: N | N21: 7124 | O21: 44578 | P21: LEPAS | Q21: 6 | R21: 171180 | S21: WO | T21: N | U21: RUSAK
A22: 7124 | B22: 01001532125 | C22: CST | D22: ORI | E22: 750 | F22: 44578 | G22: LEPAS | H22: 6 | I22: 171180 | J22: WO | K22: N | L22: RUSAK | M22: 307
A23: 7338 | B23: 01001547792 | C23: CST | D23: ORI | E23: 750 | F23: 44578 | G23: LEPAS | H23: 6 | I23: 179302 | J23: ROTASI KE POSISI 7 | K23: N | L23: MASUK GUDANG | M23: 859
A24: 7339 | B24: 01001547792 | C24: CST | D24: ORI | E24: 750 | F24: 44120 | G24: PASANG | H24: 7 | I24: 100808 | J24: PASANG BARU | K24: N
A25: 859 | B25: 01001547792 | C25: CST | D25: ORI | E25: 750 | F25: 44120 | G25: PASANG | H25: 6 | I25: 100808 | J25: PASANG BARU | K25: N | N25: 7338 | O25: 44578 | P25: LEPAS | Q25: 6 | R25: 179302 | S25: ROTASI KE POSISI 7 | T25: N | U25: MASUK GUDANG
A26: 257 | B26: 01001664064 | C26: CST | D26: ORI | E26: 750 | F26: 44120 | G26: PASANG | H26: 7 | I26: 148814 | J26: PASANG BARU | K26: N | N26: 7741 | O26: 44596 | P26: LEPAS | Q26: 7 | R26: 221797 | S26: BAN SUDAH TERLIHAT KAWAT | T26: N | U26: RUSAK
A27: 7741 | B27: 01001664064 | C27: CST | D27: ORI | E27: 750 | F27: 44596 | G27: LEPAS | H27: 7 | I27: 221797 | J27: BAN SUDAH TERLIHAT KAWAT | K27: N | L27: RUSAK | M27: 257
A28: 65 | B28: 01001721209 | C28: CST | D28: ORI | E28: 750 | F28: 44148 | G28: PASANG | H28: 4 | I28: 43715 | J28: PASANG BARU | K28: N | N28: 7245 | O28: 44580 | P28: LEPAS | Q28: 4 | R28: 131022 | S28: ROTASI KE POSISI 7 | T28: N | U28: MASUK GUDANG
A29: 7245 | B29: 01001721209 | C29: CST | D29: ORI | E29: 750 | F29: 44580 | G29: LEPAS | H29: 4 | I29: 131022 | J29: ROTASI KE POSISI 7 | K29: N | L29: MASUK GUDANG | M29: 65
A30: 7246 | B30: 01001721209 | C30: CST | D30: ORI | E30: 750 | F30: 44148 | G30: PASANG | H30: 7 | I30: 43715 | J30: PASANG BARU | K30: N
A31: 6819 | B31: 01001781105 | C31: CST | D31: ORI | E31: 750 | F31: 44151 | G31: PASANG | H31: 6 | I31: 97888 | J31: PASANG BARU | K31: N
A32: 7131 | B32: 01001781111 | C32: CST | D32: ORI | E32: 750 | F32: 44579 | G32: PASANG | H32: 7 | I32: 169162 | J32: PASANG BAN EX S 8957 UJ | K32: N
A33: 647 | B33: 0100178133 | C33: CST | D33: ORI | E33: 750 | F33: 44149 | G33: PASANG | H33: 7 | I33: 103399 | J33: PASANG BARU | K33: N
A34: 588 | B34: 01001795557 | C34: CST | D34: ORI | E34: 750 | F34: 44149 | G34: PASANG | H34: 7 | I34: 131086 | J34: PASANG BARU | K34: N
A35: 6818 | B35: 01001795601 | C35: CST | D35: ORI | E35: 750 | F35: 44151 | G35: PASANG | H35: 4 | I35: 97888 | J35: PASANG BARU | K35: N
A36: 2214 | B36: 01001880429 | C36: CST | D36: ORI | E36: 750 | F36: 44151 | G36: PASANG | H36: 6 | I36: 168011 | J36: PASANG BARU | K36: N | N36: 7822 | O36: 44597 | P36: LEPAS | Q36: 6 | R36: 242371 | S36: SPOT WEAR | T36: N | U36: RUSAK
A37: 7822 | B37: 01001880429 | C37: CST | D37: ORI | E37: 750 | F37: 44597 | G37: LEPAS | H37: 6 | I37: 242371 | J37: SPOT WEAR | K37: N | L37: RUSAK | M37: 2214
A38: 7843 | B38: 01001880431 | C38: CST | D38: ORI | E38: 750 | F38: 44341 | G38: PASANG | H38: 7 | I38: 203736 | J38: PASANG BAN EX | K38: N | N38: 7844 | O38: 44597 | P38: LEPAS | Q38: 7 | R38: 2423781 | S38: WO | T38: N | U38: MASUK GUDANG
A39: 7844 | B39: 01001880431 | C39: CST | D39: ORI | E39: 750 | F39: 44597 | G39: LEPAS | H39: 7 | I39: 2423781 | J39: WO | K39: N | L39: MASUK GUDANG | M39: 7843 | N39: 7845 | O39: 44599 | P39: PASANG | Q39: 6 | R39: 187133 | S39: PASANG BAN EX S 8978 UJ | T39: N
A40: 7845 | B40: 01001880431 | C40: CST | D40: ORI | E40: 750 | F40: 44599 | G40: PASANG | H40: 6 | I40: 187133 | J40: PASANG BAN EX S 8978 UJ | K40: N | M40: 7844
...

Sheet Umur Ban Yang Bener Lepas
A2: Status Lepas | B2: All
A3: Keterangan | B3: (Multiple Items)
A4: Tipe | B4: (Multiple Items)
A5: Status Akhir | B5: LEPAS
A7: KodeBan | B7: Tanggal | C7: Tanggal Lepas | D7: Jumlah dari Umur1 | E7: Hitung dari Nopol
A8: SP106125 | D8: 0 | E8: 1
A9: 109513 | D9: 0 | E9: 1
A10: 104744 | D10: 373 | E10: 1
A11: 108847 | D11: 750 | E11: 1
A12: 108849 | D12: 750 | E12: 1
A13: 101602 | D13: 1425 | E13: 1
A14: 012800 | D14: 6134 | E14: 1
A15: 012806 | D15: 6134 | E15: 1
A16: Y1L326140/110904 | D16: 9020 | E16: 1
A17: IJ02071855 | D17: 9149 | E17: 2
A18: 110886 | D18: 10480 | E18: 2
A19: 012781 | D19: 11005 | E19: 2
... A288: Grand Total | D288: 15293354 | E288: 396

Sheet Data Ban 750
A1: KodeBan | B1: Nopol | C1: Merk | D1: Tipe | E1: Ukuran | F1: Tanggal | G1: Status | H1: KM | I1: Posisi | J1: Keterangan | K1: Void | L1: Kondisi | M1: Status Lepas | N1: bbk | O1: Perbandingan
A2: C2135903 | B2: S 9347 UJ | C2: GY | D2: ORI | E2: 750 | F2: 43857 | G2: PASANG | H2: 49566 | I2: 7 | J2: PASANG BARU | K2: N | N2: =VLOOKUP(Tabel_Kueri1[[#This Row],[KodeBan]],'Data BBK'!C:I,7,0) -> #N/A | O2: =Tabel_Kueri1[[#This Row],[bbk]]=Tabel_Kueri1[[#This Row],[Nopol]] -> #N/A
A3: SP10665 | B3: L 8963 UJ | C3: GT | D3: ORI | E3: 750 | F3: 43904 | G3: PASANG | H3: 0 | I3: 7 | J3: BAWAAN UNIT | K3: N | N3: =VLOOKUP(Tabel_Kueri1[[#This Row],[KodeBan]],'Data BBK'!C:I,7,0) -> #N/A | O3: =Tabel_Kueri1[[#This Row],[bbk]]=Tabel_Kueri1[[#This Row],[Nopol]] -> #N/A
A4: A1889217 | B4: S 8987 UJ | C4: GY | D4: ORI | E4: 750 | F4: 43936 | G4: PASANG | H4: 120987 | I4: 7 | J4: PASANG BARU | K4: N | N4: =VLOOKUP(Tabel_Kueri1[[#This Row],[KodeBan]],'Data BBK'!C:I,7,0) -> #N/A | O4: =Tabel_Kueri1[[#This Row],[bbk]]=Tabel_Kueri1[[#This Row],[Nopol]] -> #N/A
A5: A1489084 | B5: S 9355 UJ | F5: 44019 | G5: PASANG | H5: 67597 | I5: 3 | J5: PASANG BARU | K5: N | M5: LEPAS | N5: =VLOOKUP(Tabel_Kueri1[[#This Row],[KodeBan]],'Data BBK'!C:I,7,0) -> #N/A | O5: =Tabel_Kueri1[[#This Row],[bbk]]=Tabel_Kueri1[[#This Row],[Nopol]] -> #N/A
A6: A1489200 | B6: S 9479 UJ | C6: GY | D6: ORI | E6: 750 | F6: 44020 | G6: PASANG | H6: 58483 | I6: 7 | J6: PASANG BARU | K6: N | M6: LEPAS | N6: =VLOOKUP(Tabel_Kueri1[[#This Row],[KodeBan]],'Data BBK'!C:I,7,0) -> #N/A | O6: =Tabel_Kueri1[[#This Row],[bbk]]=Tabel_Kueri1[[#This Row],[Nopol]] -> #N/A
A7: B200323086006 | B7: S 9399 UJ | C7: TK | D7: ORI | E7: 750 | F7: 44021 | G7: PASANG | H7: 92294 | I7: 7 | J7: PASANG BARU | K7: N | N7: =VLOOKUP(Tabel_Kueri1[[#This Row],[KodeBan]],'Data BBK'!C:I,7,0) -> #N/A | O7: =Tabel_Kueri1[[#This Row],[bbk]]=Tabel_Kueri1[[#This Row],[Nopol]] -> #N/A
A8: 9N0110224 | B8: S 9394 UJ | C8: ADV | D8: ORI | E8: 750 | F8: 44030 | G8: PASANG | H8: 91723 | I8: 7 | J8: PASANG BARU | K8: N | N8: =VLOOKUP(Tabel_Kueri1[[#This Row],[KodeBan]],'Data BBK'!C:I,7,0) -> #N/A | O8: =Tabel_Kueri1[[#This Row],[bbk]]=Tabel_Kueri1[[#This Row],[Nopol]] -> #N/A
A9: 9N01100390 | B9: S 9109 UJ | C9: ADV | D9: ORI | E9: 750 | F9: 44041 | G9: PASANG | H9: 141816 | I9: 3 | J9: PASANG BARU | K9: N | M9: LEPAS | N9: =VLOOKUP(Tabel_Kueri1[[#This Row],[KodeBan]],'Data BBK'!C:I,7,0) -> #N/A | O9: =Tabel_Kueri1[[#This Row],[bbk]]=Tabel_Kueri1[[#This Row],[Nopol]] -> #N/A
A10: 9N01128135 | B10: S 9359 UJ | C10: ADV | D10: ORI | E10: 750 | F10: 44048 | G10: PASANG | H10: 79429 | I10: 1 | J10: PASANG BARU | K10: N | M10: LEPAS | N10: =VLOOKUP(Tabel_Kueri1[[#This Row],[KodeBan]],'Data BBK'!C:I,7,0) -> #N/A | O10: =Tabel_Kueri1[[#This Row],[bbk]]=Tabel_Kueri1[[#This Row],[Nopol]] -> #N/A
A11: 01001352961 | B11: S 9196 UJ | C11: CST | D11: ORI | E11: 1100 | F11: 44048 | G11: PASANG | H11: 192408 | I11: 7 | J11: PASANG BARU | K11: N | M11: LEPAS | N11: =VLOOKUP(Tabel_Kueri1[[#This Row],[KodeBan]],'Data BBK'!C:I,7,0) -> #N/A | O11: =Tabel_Kueri1[[#This Row],[bbk]]=Tabel_Kueri1[[#This Row],[Nopol]] -> #N/A
A12: 9N01048266 | B12: S 9001 UJ | C12: ADV | D12: ORI | E12: 750 | F12: 44057 | G12: PASANG | H12: 140135 | I12: 5 | J12: PASANG BARU | K12: N | M12: LEPAS | N12: =VLOOKUP(Tabel_Kueri1[[#This Row],[KodeBan]],'Data BBK'!C:I,7,0) -> #N/A | O12: =Tabel_Kueri1[[#This Row],[bbk]]=Tabel_Kueri1[[#This Row],[Nopol]] -> #N/A
A13: 9N01125800 | B13: S 9608 UJ | C13: ADV | D13: ORI | E13: 750 | F13: 44062 | G13: PASANG | H13: 93621 | I13: 7 | J13: PASANG SEREP | K13: N | N13: =VLOOKUP(Tabel_Kueri1[[#This Row],[KodeBan]],'Data BBK'!C:I,7,0) -> #N/A | O13: =Tabel_Kueri1[[#This Row],[bbk]]=Tabel_Kueri1[[#This Row],[Nopol]] -> #N/A
A14: OD02084208 | B14: S 9482 UJ | C14: ADV | D14: ORI | E14: 750 | F14: 44068 | G14: PASANG | H14: 92245 | I14: 2 | J14: PASANG BARU | K14: N | M14: LEPAS | N14: =VLOOKUP(Tabel_Kueri1[[#This Row],[KodeBan]],'Data BBK'!C:I,7,0) -> #N/A | O14: =Tabel_Kueri1[[#This Row],[bbk]]=Tabel_Kueri1[[#This Row],[Nopol]] -> #N/A
A15: OD02130739 | B15: S 8985 UJ | C15: ADV | D15: ORI | E15: 750 | F15: 44068 | G15: PASANG | H15: 155435 | I15: 4 | J15: PASANG BARU | K15: N | N15: =VLOOKUP(Tabel_Kueri1[[#This Row],[KodeBan]],'Data BBK'!C:I,7,0) -> #N/A | O15: =Tabel_Kueri1[[#This Row],[bbk]]=Tabel_Kueri1[[#This Row],[Nopol]] -> #N/A
A16: OE020255268 | B16: S 8909 UJ | C16: ADV | D16: ORI | E16: 750 | F16: 44068 | G16: PASANG | H16: 151740 | I16: 7 | J16: PASANG BARU | K16: N | M16: LEPAS | N16: =VLOOKUP(Tabel_Kueri1[[#This Row],[KodeBan]],'Data BBK'!C:I,7,0) -> #N/A | O16: =Tabel_Kueri1[[#This Row],[bbk]]=Tabel_Kueri1[[#This Row],[Nopol]] -> #N/A
A17: OE020255268 | B17: S 8909 UJ | C17: ADV | D17: ORI | E17: 750 | F17: 44068 | G17: PASANG | H17: 151740 | I17: 6 | J17: PASANG BARU | K17: N | M17: LEPAS | N17: =VLOOKUP(Tabel_Kueri1[[#This Row],[KodeBan]],'Data BBK'!C:I,7,0) -> #N/A | O17: =Tabel_Kueri1[[#This Row],[bbk]]=Tabel_Kueri1[[#This Row],[Nopol]] -> #N/A
A18: 9N01052923 | B18: S 8923 UJ | C18: ADV | D18: ORI | E18: 750 | F18: 44069 | G18: PASANG | H18: 154930 | I18: 4 | J18: PASANG BARU | K18: N | N18: =VLOOKUP(Tabel_Kueri1[[#This Row],[KodeBan]],'Data BBK'!C:I,7,0) -> #N/A | O18: =Tabel_Kueri1[[#This Row],[bbk]]=Tabel_Kueri1[[#This Row],[Nopol]] -> #N/A
A19: B1572835 | B19: S 9376 UJ | C19: GY | D19: ORI | E19: 750 | F19: 44069 | G19: PASANG | H19: 96945 | I19: 6 | J19: PASANG BARU | K19: N | M19: LEPAS | N19: =VLOOKUP(Tabel_Kueri1[[#This Row],[KodeBan]],'Data BBK'!C:I,7,0) -> #N/A | O19: =Tabel_Kueri1[[#This Row],[bbk]]=Tabel_Kueri1[[#This Row],[Nopol]] -> #N/A
A20: B1470866 | B20: S 9382 UJ | C20: GY | D20: ORI | E20: 750 | F20: 44070 | G20: PASANG | H20: 101484 | I20: 7 | J20: PASANG BARU | K20: N | M20: LEPAS | N20: =VLOOKUP(Tabel_Kueri1[[#This Row],[KodeBan]],'Data BBK'!C:I,7,0) -> #N/A | O20: =Tabel_Kueri1[[#This Row],[bbk]]=Tabel_Kueri1[[#This Row],[Nopol]] -> #N/A
A21: SP10654 | B21: S 9599 UR | C21: GT | D21: VLK | E21: 750 | F21: 44083 | G21: PASANG | H21: 222601 | I21: 7 | J21: PASANG BARU | K21: N | N21: =VLOOKUP(Tabel_Kueri1[[#This Row],[KodeBan]],'Data BBK'!C:I,7,0) -> #N/A | O21: =Tabel_Kueri1[[#This Row],[bbk]]=Tabel_Kueri1[[#This Row],[Nopol]] -> #N/A
A22: 9N01046434 | B22: S 9349 UJ | C22: ADV | D22: ORI | E22: 750 | F22: 44090 | G22: PASANG | H22: 86876 | I22: 6 | J22: PASANG BARU | K22: N | M22: LEPAS | N22: =VLOOKUP(Tabel_Kueri1[[#This Row],[KodeBan]],'Data BBK'!C:I,7,0) -> #N/A | O22: =Tabel_Kueri1[[#This Row],[bbk]]=Tabel_Kueri1[[#This Row],[Nopol]] -> #N/A
A23: 9N01046086 | B23: L 8774 UJ | C23: ADV | D23: ORI | E23: 750 | F23: 44091 | G23: PASANG | H23: 32064 | I23: 1 | J23: PASANG BARU | K23: N | N23: =VLOOKUP(Tabel_Kueri1[[#This Row],[KodeBan]],'Data BBK'!C:I,7,0) -> #N/A | O23: =Tabel_Kueri1[[#This Row],[bbk]]=Tabel_Kueri1[[#This Row],[Nopol]] -> #N/A
A24: 9N01214773 | B24: S 9371 UJ | C24: ADV | D24: ORI | E24: 750 | F24: 44091 | G24: PASANG | H24: 155980 | I24: 7 | J24: PASANG BARU | K24: N | M24: LEPAS | N24: =VLOOKUP(Tabel_Kueri1[[#This Row],[KodeBan]],'Data BBK'!C:I,7,0) -> #N/A | O24: =Tabel_Kueri1[[#This Row],[bbk]]=Tabel_Kueri1[[#This Row],[Nopol]] -> #N/A
A25: 9N01214773 | B25: S 9371 UJ | C25: ADV | D25: ORI | E25: 750 | F25: 44091 | G25: PASANG | H25: 82696 | I25: 2 | J25: PASANG BARU | K25: N | M25: LEPAS | N25: =VLOOKUP(Tabel_Kueri1[[#This Row],[KodeBan]],'Data BBK'!C:I,7,0) -> #N/A | O25: =Tabel_Kueri1[[#This Row],[bbk]]=Tabel_Kueri1[[#This Row],[Nopol]] -> #N/A
A26: OH02085856 | B26: S 9002 UJ | C26: ADV | D26: ORI | E26: 750 | F26: 44095 | G26: PASANG | H26: 163856 | I26: 3 | J26: PASANG BARU | K26: N | N26: =VLOOKUP(Tabel_Kueri1[[#This Row],[KodeBan]],'Data BBK'!C:I,7,0) -> #N/A | O26: =Tabel_Kueri1[[#This Row],[bbk]]=Tabel_Kueri1[[#This Row],[Nopol]] -> #N/A
A27: OG02232854 | B27: S 9235 UJ | C27: ADV | D27: ORI | E27: 1100 | F27: 44096 | G27: PASANG | H27: 179321 | I27: 10 | J27: PASANG BARU | K27: N | M27: LEPAS | N27: =VLOOKUP(Tabel_Kueri1[[#This Row],[KodeBan]],'Data BBK'!C:I,7,0) -> #N/A | O27: =Tabel_Kueri1[[#This Row],[bbk]]=Tabel_Kueri1[[#This Row],[Nopol]] -> #N/A
A28: OH02073785 | B28: S 9132 UJ | C28: ADV | D28: ORI | E28: 750 | F28: 44096 | G28: PASANG | H28: 190650 | I28: 2 | J28: PASANG BARU | K28: N | N28: =VLOOKUP(Tabel_Kueri1[[#This Row],[KodeBan]],'Data BBK'!C:I,7,0) -> #N/A | O28: =Tabel_Kueri1[[#This Row],[bbk]]=Tabel_Kueri1[[#This Row],[Nopol]] -> #N/A
A29: OH02085862 | B29: S 9347 UJ | C29: ADV | D29: ORI | E29: 750 | F29: 44103 | G29: PASANG | H29: 85112 | I29: 5 | J29: PASANG BARU | K29: N | N29: =VLOOKUP(Tabel_Kueri1[[#This Row],[KodeBan]],'Data BBK'!C:I,7,0) -> #N/A | O29: =Tabel_Kueri1[[#This Row],[bbk]]=Tabel_Kueri1[[#This Row],[Nopol]] -> #N/A
A30: 01002107077 | B30: S 9699 UR | C30: CST | D30: ORI | E30: 750 | F30: 44105 | G30: PASANG | H30: 257915 | I30: 1 | J30: PASANG BARU | K30: N | N30: =VLOOKUP(Tabel_Kueri1[[#This Row],[KodeBan]],'Data BBK'!C:I,7,0) -> #N/A | O30: =Tabel_Kueri1[[#This Row],[bbk]]=Tabel_Kueri1[[#This Row],[Nopol]] -> #N/A
A31: 01002121303 | B31: S 8962 UJ | C31: CST | D31: ORI | E31: 750 | F31: 44105 | G31: PASANG | H31: 158179 | I31: 6 | J31: PASANG BARU | K31: N | M31: LEPAS | N31: =VLOOKUP(Tabel_Kueri1[[#This Row],[KodeBan]],'Data BBK'!C:I,7,0) -> #N/A | O31: =Tabel_Kueri1[[#This Row],[bbk]]=Tabel_Kueri1[[#This Row],[Nopol]] -> #N/A
A32: 1002120471 | B32: S 9574 UJ | F32: 44105 | G32: PASANG | H32: 105555 | I32: 7 | J32: PASANG BARU | K32: N | N32: =VLOOKUP(Tabel_Kueri1[[#This Row],[KodeBan]],'Data BBK'!C:I,7,0) -> #N/A | O32: =Tabel_Kueri1[[#This Row],[bbk]]=Tabel_Kueri1[[#This Row],[Nopol]] -> #N/A
A33: OG02231868 | B33: S 9181 UJ | C33: ADV | D33: ORI | E33: 1100 | F33: 44107 | G33: PASANG | H33: 201555 | I33: 7 | J33: PASANG BARU | K33: N | M33: LEPAS | N33: =VLOOKUP(Tabel_Kueri1[[#This Row],[KodeBan]],'Data BBK'!C:I,7,0) -> #N/A | O33: =Tabel_Kueri1[[#This Row],[bbk]]=Tabel_Kueri1[[#This Row],[Nopol]] -> #N/A
A34: 01002025615 | B34: S 9515 UJ | C34: CST | D34: ORI | E34: 750 | F34: 44116 | G34: PASANG | H34: 103123 | I34: 4 | J34: PASANG BARU | K34: N | M34: LEPAS | N34: =VLOOKUP(Tabel_Kueri1[[#This Row],[KodeBan]],'Data BBK'!C:I,7,0) -> #N/A | O34: =Tabel_Kueri1[[#This Row],[bbk]]=Tabel_Kueri1[[#This Row],[Nopol]] -> #N/A
A35: 01001518713 | B35: S 9383 UJ | C35: CST | D35: ORI | E35: 750 | F35: 44120 | G35: PASANG | H35: 106211 | I35: 7 | J35: PASANG BARU | K35: N | N35: =VLOOKUP(Tabel_Kueri1[[#This Row],[KodeBan]],'Data BBK'!C:I,7,0) -> #N/A | O35: =Tabel_Kueri1[[#This Row],[bbk]]=Tabel_Kueri1[[#This Row],[Nopol]] -> #N/A
A36: 01001532125 | B36: S 9572 UJ | C36: CST | D36: ORI | E36: 750 | F36: 44120 | G36: PASANG | H36: 93229 | I36: 6 | J36: PASANG BARU | K36: N | M36: LEPAS | N36: =VLOOKUP(Tabel_Kueri1[[#This Row],[KodeBan]],'Data BBK'!C:I,7,0) -> #N/A | O36: =Tabel_Kueri1[[#This Row],[bbk]]=Tabel_Kueri1[[#This Row],[Nopol]] -> #N/A
A37: 01001547792 | B37: S 9472 UJ | C37: CST | D37: ORI | E37: 750 | F37: 44120 | G37: PASANG | H37: 100808 | I37: 6 | J37: PASANG BARU | K37: N | M37: LEPAS | N37: =VLOOKUP(Tabel_Kueri1[[#This Row],[KodeBan]],'Data BBK'!C:I,7,0) -> #N/A | O37: =Tabel_Kueri1[[#This Row],[bbk]]=Tabel_Kueri1[[#This Row],[Nopol]] -> #N/A
A38: 01001547792 | B38: S 9472 UJ | C38: CST | D38: ORI | E38: 750 | F38: 44120 | G38: PASANG | H38: 100808 | I38: 7 | J38: PASANG BARU | K38: N | M38: LEPAS | N38: =VLOOKUP(Tabel_Kueri1[[#This Row],[KodeBan]],'Data BBK'!C:I,7,0) -> #N/A | O38: =Tabel_Kueri1[[#This Row],[bbk]]=Tabel_Kueri1[[#This Row],[Nopol]] -> #N/A
A39: 01001664064 | B39: S 8867 UJ | C39: CST | D39: ORI | E39: 750 | F39: 44120 | G39: PASANG | H39: 148814 | I39: 7 | J39: PASANG BARU | K39: N | M39: LEPAS | N39: =VLOOKUP(Tabel_Kueri1[[#This Row],[KodeBan]],'Data BBK'!C:I,7,0) -> #N/A | O39: =Tabel_Kueri1[[#This Row],[bbk]]=Tabel_Kueri1[[#This Row],[Nopol]] -> #N/A
A40: 201016/01000517781 | B40: S 9376 UJ | C40: CST | D40: ORI | E40: 750 | F40: 44120 | G40: PASANG | H40: 104930 | I40: 4 | J40: PASANG BARU | K40: N | M40: LEPAS | N40: =VLOOKUP(Tabel_Kueri1[[#This Row],[KodeBan]],'Data BBK'!C:I,7,0) -> #N/A | O40: =Tabel_Kueri1[[#This Row],[bbk]]=Tabel_Kueri1[[#This Row],[Nopol]] -> #N/A
...

Sheet Data TrackBan
A1: ID | B1: Nopol | C1: KodeBan | D1: Tanggal | E1: Status | F1: Posisi | G1: KM | H1: Keterangan | I1: Void | J1: Ref | K1: Kondisi
A2: 39 | B2: L 8502 UO | C2: 104173 | D2: 44292 | E2: PASANG | F2: 5 | G2: 59859 | H2: PASANG BARU | I2: N | J2: 0
A3: 46 | B3: S 9457 UJ | C3: 104188 | D3: 44295 | E3: PASANG | F3: 5 | G3: 180185 | H3: PASANG BARU | I3: N | J3: 0
A4: 67 | B4: L 8774 UJ | C4: 102031 | D4: 44236 | E4: PASANG | F4: 5 | G4: 62722 | H4: PASANG BARU | I4: N | J4: 0
A5: 72 | B5: L 8967 UJ | C5: 102024 | D5: 44243 | E5: PASANG | F5: 5 | G5: 40241 | H5: PASANG BARU | I5: N | J5: 0
A6: 80 | B6: S 8909 UJ | C6: 012768 | D6: 44543 | E6: PASANG | F6: 5 | G6: 245783 | H6: PASANG BARU | I6: N | J6: 0
A7: 84 | B7: S 8941 UJ | C7: 110620 | D7: 44481 | E7: PASANG | F7: 5 | G7: 219943 | H7: PASANG BARU | I7: N | J7: 0
A8: 92 | B8: S 8954 UJ | C8: 109507 | D8: 44449 | E8: PASANG | F8: 5 | G8: 216525 | H8: PASANG BARU | I8: N | J8: 0
A9: 101 | B9: S 8962 UJ | C9: 110610 | D9: 44476 | E9: PASANG | F9: 5 | G9: 223241 | H9: PASANG BARU | I9: N | J9: 0
A10: 107 | B10: S 9032 UJ | C10: 012798 | D10: 44548 | E10: PASANG | F10: 5 | G10: 228086 | H10: PASANG BARU | I10: N | J10: 0
A11: 111 | B11: S 9042 UJ | C11: 105258 | D11: 44322 | E11: PASANG | F11: 5 | G11: 178513 | H11: PASANG BARU | I11: N | J11: 0
A12: 121 | B12: S 9132 UJ | C12: 109495 | D12: 44441 | E12: PASANG | F12: 5 | G12: 236519 | H12: PASANG BARU | I12: N | J12: 0
A13: 131 | B13: S 9308 UK | C13: 106294 | D13: 44357 | E13: PASANG | F13: 5 | G13: 28033 | H13: PASANG BARU | I13: N | J13: 0
... A2202: 8006 | B2202: AD 8125 OY | C2202: SP106112.1-8125 | D2202: 44414 | E2202: PASANG | F2202: 7 | G2202: 0 | H2202: BAWAAN UNIT | I2202: N | J2202: 0
A2203: 4690 | B2203: S 9413 UJ | C2203: SP106125 | D2203: 44585 | E2203: LEPAS | F2203: 5 | G2203: 206385 | H2203: ROTASI PINDAH KE POSISI 7 | I2203: N | J2203: 797 | K2203: MASUK GUDANG
A2204: 4694 | B2204: S 9413 UJ | C2204: 104179 | D2204: 44582 | E2204: LEPAS | F2204: 7 | G2204: 206385 | H2204: CBU | I2204: N | J2204: 791 | K2204: RUSAK
A2205: 4701 | B2205: S 9362 UJ | C2205: SPS 21-05-018 | D2205: 44565 | E2205: LEPAS | F2205: 7 | G2205: 326985 | H2205: OPER B 9363 PYU | I2205: N | J2205: 4483 | K2205: MASUK GUDANG
A2206: 4702 | B2206: S 9362 UJ | C2206: 102620 | D2206: 44565 | E2206: LEPAS | F2206: 9 | G2206: 326985 | H2206: ROTASI KE POSISI 11 | I2206: N | J2206: 4700 | K2206: MASUK GUDANG
A2207: 4703 | B2207: S 9362 UJ | C2207: YOY328461 | D2207: 44565 | E2207: LEPAS | F2207: 11 | G2207: 326985 | H2207: RADIAL SPLIT | I2207: N | J2207: 4493 | K2207: RUSAK
A2208: 4720 | B2208: S 9109 UJ | C2208: 105245 | D2208: 44566 | E2208: LEPAS | F2208: 1 | G2208: 241147 | H2208: ROTASI KE POSISI 3 | I2208: N | J2208: 4717 | K2208: MASUK GUDANG
A2209: 4721 | B2209: S 9109 UJ | C2209: 105246 | D2209: 44566 | E2209: LEPAS | F2209: 2 | G2209: 241147 | H2209: ROTASI KE POSISI 5 | I2209: N | J2209: 4718 | K2209: MASUK GUDANG
A2210: 4726 | B2210: S 9109 UJ | C2210: 103112 | D2210: 44566 | E2210: LEPAS | F2210: 5 | G2210: 241147 | H2210: ROTASI KE POSISI 7 | I2210: N | J2210: 4725 | K2210: MASUK GUDANG
A2211: 4727 | B2211: S 9109 UJ | C2211: 9N01100390 | D2211: 44566 | E2211: LEPAS | F2211: 3 | G2211: 241147 | H2211: SIDE CUT | I2211: N | J2211: 4724 | K2211: MASUK GUDANG
A2212: 4731 | B2212: S 9109 UJ | C2212: ESK86762 | D2212: 44566 | E2212: LEPAS | F2212: 7 | G2212: 241147 | H2212: SEPARATION | I2212: N | J2212: 4730 | K2212: RUSAK
A2213: 4733 | B2213: L 8502 UO | C2213: T89018502/201112 | D2213: 44567 | E2213: LEPAS | F2213: 7 | G2213: 109635 | H2213: SHOCK BURST | I2213: N | J2213: 42 | K2213: RUSAK
A2214: 4738 | B2214: S 9152 UJ | C2214: 104174 | D2214: 44565 | E2214: LEPAS | F2214: 3 | G2214: 221094 | H2214: SIDE CUT PENETRATION | I2214: N | J2214: 4735 | K2214: RUSAK
... A2681: 7986 | B2681: AD 8064 OY | C2681: 102025/01003824780 | D2681: 44586 | E2681: LEPAS | F2681: 7 | G2681: 54257 | H2681: WO | I2681: N | J2681: 4292 | K2681: MASUK GUDANG
